Watching for file changes with StatReloader
C:\Users\USER\AIFaceRecognized\backend\attendance\views.py changed, reloading.
Watching for file changes with StatReloader
Watching for file changes with StatReloader
C:\Users\USER\AIFaceRecognized\backend\attendance\models.py changed, reloading.
Watching for file changes with StatReloader
Watching for file changes with StatReloader
"OPTIONS /api/auth/login/ HTTP/1.1" 200 0
Internal Server Error: /api/auth/login/
Traceback (most recent call last):
  File "C:\Users\USER\AIFaceRecognized\backend\venv\Lib\site-packages\django\db\backends\utils.py", line 89, in _execute
    return self.cursor.execute(sql, params)
           ^^^^^^^^^^^^^^^^^^^^^^^^^^^^^^^^
  File "C:\Users\USER\AIFaceRecognized\backend\venv\Lib\site-packages\django\db\backends\sqlite3\base.py", line 328, in execute
    return super().execute(query, params)
           ^^^^^^^^^^^^^^^^^^^^^^^^^^^^^^
sqlite3.OperationalError: no such table: users

The above exception was the direct cause of the following exception:

Traceback (most recent call last):
  File "C:\Users\USER\AIFaceRecognized\backend\venv\Lib\site-packages\django\core\handlers\exception.py", line 55, in inner
    response = get_response(request)
               ^^^^^^^^^^^^^^^^^^^^^
  File "C:\Users\USER\AIFaceRecognized\backend\venv\Lib\site-packages\django\core\handlers\base.py", line 197, in _get_response
    response = wrapped_callback(request, *callback_args, **callback_kwargs)
               ^^^^^^^^^^^^^^^^^^^^^^^^^^^^^^^^^^^^^^^^^^^^^^^^^^^^^^^^^^^^
  File "C:\Users\USER\AIFaceRecognized\backend\venv\Lib\site-packages\django\views\decorators\csrf.py", line 56, in wrapper_view
    return view_func(*args, **kwargs)
           ^^^^^^^^^^^^^^^^^^^^^^^^^^
  File "C:\Users\USER\AIFaceRecognized\backend\venv\Lib\site-packages\django\views\generic\base.py", line 104, in view
    return self.dispatch(request, *args, **kwargs)
           ^^^^^^^^^^^^^^^^^^^^^^^^^^^^^^^^^^^^^^^
  File "C:\Users\USER\AIFaceRecognized\backend\venv\Lib\site-packages\rest_framework\views.py", line 509, in dispatch
    response = self.handle_exception(exc)
               ^^^^^^^^^^^^^^^^^^^^^^^^^^
  File "C:\Users\USER\AIFaceRecognized\backend\venv\Lib\site-packages\rest_framework\views.py", line 469, in handle_exception
    self.raise_uncaught_exception(exc)
  File "C:\Users\USER\AIFaceRecognized\backend\venv\Lib\site-packages\rest_framework\views.py", line 480, in raise_uncaught_exception
    raise exc
  File "C:\Users\USER\AIFaceRecognized\backend\venv\Lib\site-packages\rest_framework\views.py", line 506, in dispatch
    response = handler(request, *args, **kwargs)
               ^^^^^^^^^^^^^^^^^^^^^^^^^^^^^^^^^
  File "C:\Users\USER\AIFaceRecognized\backend\venv\Lib\site-packages\rest_framework_simplejwt\views.py", line 44, in post
    serializer.is_valid(raise_exception=True)
  File "C:\Users\USER\AIFaceRecognized\backend\venv\Lib\site-packages\rest_framework\serializers.py", line 227, in is_valid
    self._validated_data = self.run_validation(self.initial_data)
                           ^^^^^^^^^^^^^^^^^^^^^^^^^^^^^^^^^^^^^^
  File "C:\Users\USER\AIFaceRecognized\backend\venv\Lib\site-packages\rest_framework\serializers.py", line 429, in run_validation
    value = self.validate(value)
            ^^^^^^^^^^^^^^^^^^^^
  File "C:\Users\USER\AIFaceRecognized\backend\venv\Lib\site-packages\rest_framework_simplejwt\serializers.py", line 73, in validate
    data = super().validate(attrs)
           ^^^^^^^^^^^^^^^^^^^^^^^
  File "C:\Users\USER\AIFaceRecognized\backend\venv\Lib\site-packages\rest_framework_simplejwt\serializers.py", line 54, in validate
    self.user = authenticate(**authenticate_kwargs)
                ^^^^^^^^^^^^^^^^^^^^^^^^^^^^^^^^^^^
  File "C:\Users\USER\AIFaceRecognized\backend\venv\Lib\site-packages\django\views\decorators\debug.py", line 42, in sensitive_variables_wrapper
    return func(*func_args, **func_kwargs)
           ^^^^^^^^^^^^^^^^^^^^^^^^^^^^^^^
  File "C:\Users\USER\AIFaceRecognized\backend\venv\Lib\site-packages\django\contrib\auth\__init__.py", line 77, in authenticate
    user = backend.authenticate(request, **credentials)
           ^^^^^^^^^^^^^^^^^^^^^^^^^^^^^^^^^^^^^^^^^^^^
  File "C:\Users\USER\AIFaceRecognized\backend\venv\Lib\site-packages\django\contrib\auth\backends.py", line 46, in authenticate
    user = UserModel._default_manager.get_by_natural_key(username)
           ^^^^^^^^^^^^^^^^^^^^^^^^^^^^^^^^^^^^^^^^^^^^^^^^^^^^^^^
  File "C:\Users\USER\AIFaceRecognized\backend\venv\Lib\site-packages\django\contrib\auth\base_user.py", line 54, in get_by_natural_key
    return self.get(**{self.model.USERNAME_FIELD: username})
           ^^^^^^^^^^^^^^^^^^^^^^^^^^^^^^^^^^^^^^^^^^^^^^^^^
  File "C:\Users\USER\AIFaceRecognized\backend\venv\Lib\site-packages\django\db\models\manager.py", line 87, in manager_method
    return getattr(self.get_queryset(), name)(*args, **kwargs)
           ^^^^^^^^^^^^^^^^^^^^^^^^^^^^^^^^^^^^^^^^^^^^^^^^^^^
  File "C:\Users\USER\AIFaceRecognized\backend\venv\Lib\site-packages\django\db\models\query.py", line 633, in get
    num = len(clone)
          ^^^^^^^^^^
  File "C:\Users\USER\AIFaceRecognized\backend\venv\Lib\site-packages\django\db\models\query.py", line 380, in __len__
    self._fetch_all()
  File "C:\Users\USER\AIFaceRecognized\backend\venv\Lib\site-packages\django\db\models\query.py", line 1881, in _fetch_all
    self._result_cache = list(self._iterable_class(self))
                         ^^^^^^^^^^^^^^^^^^^^^^^^^^^^^^^^
  File "C:\Users\USER\AIFaceRecognized\backend\venv\Lib\site-packages\django\db\models\query.py", line 91, in __iter__
    results = compiler.execute_sql(
              ^^^^^^^^^^^^^^^^^^^^^
  File "C:\Users\USER\AIFaceRecognized\backend\venv\Lib\site-packages\django\db\models\sql\compiler.py", line 1562, in execute_sql
    cursor.execute(sql, params)
  File "C:\Users\USER\AIFaceRecognized\backend\venv\Lib\site-packages\django\db\backends\utils.py", line 102, in execute
    return super().execute(sql, params)
           ^^^^^^^^^^^^^^^^^^^^^^^^^^^^
  File "C:\Users\USER\AIFaceRecognized\backend\venv\Lib\site-packages\django\db\backends\utils.py", line 67, in execute
    return self._execute_with_wrappers(
           ^^^^^^^^^^^^^^^^^^^^^^^^^^^^
  File "C:\Users\USER\AIFaceRecognized\backend\venv\Lib\site-packages\django\db\backends\utils.py", line 80, in _execute_with_wrappers
    return executor(sql, params, many, context)
           ^^^^^^^^^^^^^^^^^^^^^^^^^^^^^^^^^^^^
  File "C:\Users\USER\AIFaceRecognized\backend\venv\Lib\site-packages\django\db\backends\utils.py", line 84, in _execute
    with self.db.wrap_database_errors:
         ^^^^^^^^^^^^^^^^^^^^^^^^^^^^
  File "C:\Users\USER\AIFaceRecognized\backend\venv\Lib\site-packages\django\db\utils.py", line 91, in __exit__
    raise dj_exc_value.with_traceback(traceback) from exc_value
  File "C:\Users\USER\AIFaceRecognized\backend\venv\Lib\site-packages\django\db\backends\utils.py", line 89, in _execute
    return self.cursor.execute(sql, params)
           ^^^^^^^^^^^^^^^^^^^^^^^^^^^^^^^^
  File "C:\Users\USER\AIFaceRecognized\backend\venv\Lib\site-packages\django\db\backends\sqlite3\base.py", line 328, in execute
    return super().execute(query, params)
           ^^^^^^^^^^^^^^^^^^^^^^^^^^^^^^
django.db.utils.OperationalError: no such table: users
"POST /api/auth/login/ HTTP/1.1" 500 213425
Watching for file changes with StatReloader
"OPTIONS /api/auth/register/ HTTP/1.1" 200 0
"POST /api/auth/register/ HTTP/1.1" 201 696
"OPTIONS /api/attendance/dashboard-stats/ HTTP/1.1" 200 0
"OPTIONS /api/attendance/dashboard-stats/ HTTP/1.1" 200 0
"GET /api/attendance/dashboard-stats/ HTTP/1.1" 200 167
"GET /api/attendance/dashboard-stats/ HTTP/1.1" 200 167
"OPTIONS /api/face-recognition/mark-attendance/ HTTP/1.1" 200 0
Not Found: /api/face-recognition/mark-attendance/
"POST /api/face-recognition/mark-attendance/ HTTP/1.1" 404 3288
"GET /api/attendance/dashboard-stats/ HTTP/1.1" 200 167
"GET /api/attendance/dashboard-stats/ HTTP/1.1" 200 167
Unauthorized: /api/auth/login/
"POST /api/auth/login/ HTTP/1.1" 401 63
Unauthorized: /api/auth/login/
"POST /api/auth/login/ HTTP/1.1" 401 63
"POST /api/auth/login/ HTTP/1.1" 200 483
"POST /api/auth/login/ HTTP/1.1" 200 483
"POST /api/auth/login/ HTTP/1.1" 200 483
"POST /api/auth/login/ HTTP/1.1" 200 483
"POST /api/auth/login/ HTTP/1.1" 200 483
"POST /api/auth/login/ HTTP/1.1" 200 483
"POST /api/auth/login/ HTTP/1.1" 200 483
"POST /api/auth/login/ HTTP/1.1" 200 483
"POST /api/auth/login/ HTTP/1.1" 200 483
"GET /api/attendance/dashboard-stats/ HTTP/1.1" 200 167
"GET /api/attendance/dashboard-stats/ HTTP/1.1" 200 167
C:\Users\USER\AIFaceRecognized\backend\attendance_system\urls.py changed, reloading.
Watching for file changes with StatReloader
"POST /api/auth/login/ HTTP/1.1" 200 696
"GET /api/attendance/dashboard-stats/ HTTP/1.1" 200 167
"GET /api/attendance/dashboard-stats/ HTTP/1.1" 200 167
"GET /api/attendance/dashboard-stats/ HTTP/1.1" 200 167
"GET /api/attendance/dashboard-stats/ HTTP/1.1" 200 167
"GET /api/attendance/dashboard-stats/ HTTP/1.1" 200 167
"OPTIONS /api/face/register/ HTTP/1.1" 200 0
"POST /api/face/register/ HTTP/1.1" 200 172
"GET /api/attendance/dashboard-stats/ HTTP/1.1" 200 167
"GET /api/attendance/dashboard-stats/ HTTP/1.1" 200 167
"POST /api/face/register/ HTTP/1.1" 200 173
"GET /api/attendance/dashboard-stats/ HTTP/1.1" 200 167
"GET /api/attendance/dashboard-stats/ HTTP/1.1" 200 167
"OPTIONS /api/face/attendance/ HTTP/1.1" 200 0
"POST /api/face/attendance/ HTTP/1.1" 200 150
"GET /api/attendance/dashboard-stats/ HTTP/1.1" 200 169
"GET /api/attendance/dashboard-stats/ HTTP/1.1" 200 169
"GET /api/attendance/dashboard-stats/ HTTP/1.1" 200 169
"GET /api/attendance/dashboard-stats/ HTTP/1.1" 200 169
Bad Request: /api/face/attendance/
"POST /api/face/attendance/ HTTP/1.1" 400 47
Bad Request: /api/face/attendance/
"POST /api/face/attendance/ HTTP/1.1" 400 47
Bad Request: /api/face/attendance/
"POST /api/face/attendance/ HTTP/1.1" 400 47
Bad Request: /api/face/attendance/
"POST /api/face/attendance/ HTTP/1.1" 400 47
C:\Users\USER\AIFaceRecognized\backend\accounts\models.py changed, reloading.
Watching for file changes with StatReloader
C:\Users\USER\AIFaceRecognized\backend\attendance_system\settings.py changed, reloading.
Watching for file changes with StatReloader
C:\Users\USER\AIFaceRecognized\backend\attendance_system\urls.py changed, reloading.
Watching for file changes with StatReloader
